<?xml version="1.0" ?>
<sdf version="1.8">
    <model name='courier_robot'>
        <pose>0 0 0.1 0 0 0</pose>
        
        <!-- Base link (main robot frame) -->
        <link name='base_link'>
            <pose>0 0 0 0 0 0</pose>
            <inertial>
                <mass>0.01</mass>
                <inertia>
                    <ixx>0.0001</ixx> <ixy>0</ixy> <ixz>0</ixz>
                    <iyy>0.0001</iyy> <iyz>0</iyz> <izz>0.0001</izz>
                </inertia>
            </inertial>
        </link>
        
        <!-- Base footprint (ground projection) -->
        <link name='base_footprint'>
            <pose>0 0 -0.1 0 0 0</pose>
        </link>
        <joint name='base_footprint_joint' type='fixed'>
            <parent>base_link</parent>
            <child>base_footprint</child>
        </joint>
        
        <link name='chassis'>
            <pose>-0.1 0 0 0 0 0</pose>
            <inertial>
                <mass>1.14395</mass>
                <inertia>
                    <ixx>0.095329</ixx> <ixy>0</ixy> <ixz>0</ixz>
                    <iyy>0.381317</iyy> <iyz>0</iyz> <izz>0.476646</izz>
                </inertia>
            </inertial>
            <visual name='visual'>
                <geometry><box><size>0.4 0.4 0.15</size></box></geometry>
                <material><ambient>0.8 0.8 0.8 1</ambient><diffuse>0.8 0.8 0.8 1</diffuse></material>
            </visual>
            <collision name='collision'>
                <geometry><box><size>0.4 0.4 0.15</size></box></geometry>
            </collision>
        </link>

        <link name='left_wheel'>
            <pose>0 0.22 0 -1.5707 0 0</pose>
            <inertial>
                <mass>1</mass>
                <inertia>
                    <ixx>0.043333</ixx> <ixy>0</ixy> <ixz>0</ixz>
                    <iyy>0.043333</iyy> <iyz>0</iyz> <izz>0.08</izz>
                </inertia>
            </inertial>
            <visual name='visual'>
                <geometry><cylinder><radius>0.1</radius><length>0.04</length></cylinder></geometry>
                <material><ambient>0.2 0.2 0.2 1</ambient><diffuse>0.2 0.2 0.2 1</diffuse></material>
            </visual>
            <collision name='collision'>
                <geometry><cylinder><radius>0.1</radius><length>0.04</length></cylinder></geometry>
            </collision>
        </link>

        <link name='right_wheel'>
            <pose>0 -0.22 0 -1.5707 0 0</pose>
            <inertial>
                <mass>1</mass>
                <inertia>
                    <ixx>0.043333</ixx> <ixy>0</ixy> <ixz>0</ixz>
                    <iyy>0.043333</iyy> <iyz>0</iyz> <izz>0.08</izz>
                </inertia>
            </inertial>
            <visual name='visual'>
                <geometry><cylinder><radius>0.1</radius><length>0.04</length></cylinder></geometry>
                <material><ambient>0.2 0.2 0.2 1</ambient><diffuse>0.2 0.2 0.2 1</diffuse></material>
            </visual>
            <collision name='collision'>
                <geometry><cylinder><radius>0.1</radius><length>0.04</length></cylinder></geometry>
            </collision>
        </link>

        <joint name='left_wheel_joint' type='revolute'>
            <parent>chassis</parent>
            <child>left_wheel</child>
            <axis><xyz>0 0 1</xyz></axis>
        </joint>
        <joint name='right_wheel_joint' type='revolute'>
            <parent>chassis</parent>
            <child>right_wheel</child>
            <axis><xyz>0 0 1</xyz></axis>
        </joint>
        <joint name='chassis_joint' type='fixed'>
            <parent>base_link</parent>
            <child>chassis</child>
        </joint>

        <link name='caster'>
            <pose>-0.3 0 -0.05 0 0 0</pose>
            <collision name='collision'><geometry><sphere><radius>0.05</radius></sphere></geometry></collision>
        </link>
        <joint name='caster_wheel' type='ball'>
            <parent>chassis</parent>
            <child>caster</child>
        </joint>

        <!-- IMU Sensor -->
        <link name='imu_link'>
            <pose>0 0 0.1 0 0 0</pose>
            <inertial>
                <mass>0.01</mass>
                <inertia>
                    <ixx>0.0001</ixx> <ixy>0</ixy> <ixz>0</ixz>
                    <iyy>0.0001</iyy> <iyz>0</iyz> <izz>0.0001</izz>
                </inertia>
            </inertial>
            <sensor name='imu_sensor' type='imu'>
                <always_on>1</always_on>
                <update_rate>20</update_rate>
                <imu>
                    <angular_velocity>
                        <x><noise type="gaussian"><mean>0</mean><stddev>0.009</stddev></noise></x>
                        <y><noise type="gaussian"><mean>0</mean><stddev>0.009</stddev></noise></y>
                        <z><noise type="gaussian"><mean>0</mean><stddev>0.009</stddev></noise></z>
                    </angular_velocity>
                    <linear_acceleration>
                        <x><noise type="gaussian"><mean>0</mean><stddev>0.017</stddev></noise></x>
                        <y><noise type="gaussian"><mean>0</mean><stddev>0.017</stddev></noise></y>
                        <z><noise type="gaussian"><mean>0</mean><stddev>0.017</stddev></noise></z>
                    </linear_acceleration>
                </imu>
                <topic>imu</topic>
            </sensor>
        </link>
        <joint name='imu_joint' type='fixed'>
            <parent>chassis</parent>
            <child>imu_link</child>
        </joint>

        <!-- Gripper/Arm -->
        <link name='gripper'>
            <pose>0.2 0 0.05 0 0 0</pose>
            <inertial>
                <mass>0.1</mass>
                <inertia>
                    <ixx>0.0001</ixx> <ixy>0</ixy> <ixz>0</ixz>
                    <iyy>0.0001</iyy> <iyz>0</iyz> <izz>0.0001</izz>
                </inertia>
            </inertial>
            <visual name='arm_visual'>
                <geometry><box><size>0.15 0.05 0.05</size></box></geometry>
                <material><ambient>1 0.5 0 1</ambient><diffuse>1 0.5 0 1</diffuse></material>
            </visual>
            <visual name='gripper_left'>
                <pose>0.08 0.03 0 0 0 0</pose>
                <geometry><box><size>0.02 0.02 0.08</size></box></geometry>
                <material><ambient>0.3 0.3 0.3 1</ambient><diffuse>0.3 0.3 0.3 1</diffuse></material>
            </visual>
            <visual name='gripper_right'>
                <pose>0.08 -0.03 0 0 0 0</pose>
                <geometry><box><size>0.02 0.02 0.08</size></box></geometry>
                <material><ambient>0.3 0.3 0.3 1</ambient><diffuse>0.3 0.3 0.3 1</diffuse></material>
            </visual>
        </link>
        <joint name='gripper_joint' type='fixed'>
            <parent>chassis</parent>
            <child>gripper</child>
        </joint>

        <!-- Camera for AprilTag detection -->
        <link name='camera_link'>
            <pose>0.15 0 0.15 0 0 0</pose>
            <inertial>
                <mass>0.05</mass>
                <inertia>
                    <ixx>0.0001</ixx> <ixy>0</ixy> <ixz>0</ixz>
                    <iyy>0.0001</iyy> <iyz>0</iyz> <izz>0.0001</izz>
                </inertia>
            </inertial>
            <visual name='camera_visual'>
                <geometry><box><size>0.03 0.08 0.03</size></box></geometry>
                <material><ambient>0.1 0.1 0.1 1</ambient><diffuse>0.1 0.1 0.1 1</diffuse></material>
            </visual>
            <sensor name='camera' type='camera'>
                <update_rate>10</update_rate>
                <camera>
                    <horizontal_fov>1.047</horizontal_fov>
                    <image>
                        <width>320</width>
                        <height>240</height>
                    </image>
                    <clip>
                        <near>0.1</near>
                        <far>10</far>
                    </clip>
                </camera>
                <always_on>1</always_on>
                <visualize>true</visualize>
                <topic>camera</topic>
            </sensor>
        </link>
        <joint name='camera_joint' type='fixed'>
            <parent>chassis</parent>
            <child>camera_link</child>
        </joint>

        <!-- Lidar for navigation and localization -->
        <link name='lidar_link'>
            <pose>0 0 0.2 0 0 0</pose>
            <inertial>
                <mass>0.1</mass>
                <inertia>
                    <ixx>0.0001</ixx> <ixy>0</ixy> <ixz>0</ixz>
                    <iyy>0.0001</iyy> <iyz>0</iyz> <izz>0.0001</izz>
                </inertia>
            </inertial>
            <visual name='lidar_visual'>
                <geometry><cylinder><radius>0.05</radius><length>0.04</length></cylinder></geometry>
                <material><ambient>0.0 0.0 0.0 1</ambient><diffuse>0.0 0.0 0.0 1</diffuse></material>
            </visual>
            <sensor name='gpu_lidar' type='gpu_lidar'>
                <update_rate>10</update_rate>
                <lidar>
                    <scan>
                        <horizontal>
                            <samples>360</samples>
                            <resolution>1</resolution>
                            <min_angle>-3.14159</min_angle>
                            <max_angle>3.14159</max_angle>
                        </horizontal>
                    </scan>
                    <range>
                        <min>0.15</min>
                        <max>6.0</max>
                        <resolution>0.01</resolution>
                    </range>
                    <noise>
                        <type>gaussian</type>
                        <mean>0</mean>
                        <stddev>0.01</stddev>
                    </noise>
                </lidar>
                <always_on>1</always_on>
                <visualize>true</visualize>
                <topic>scan</topic>
            </sensor>
        </link>
        <joint name='lidar_joint' type='fixed'>
            <parent>chassis</parent>
            <child>lidar_link</child>
        </joint>

        <plugin filename="gz-sim-diff-drive-system" name="gz::sim::systems::DiffDrive">
            <left_joint>left_wheel_joint</left_joint>
            <right_joint>right_wheel_joint</right_joint>
            <wheel_separation>0.44</wheel_separation>
            <wheel_radius>0.1</wheel_radius>
            <topic>cmd_vel</topic>
            <odom_topic>odom</odom_topic>
            <tf_topic>tf</tf_topic>
            <frame_id>odom</frame_id>
            <child_frame_id>base_link</child_frame_id>
        </plugin>
    </model>
</sdf>
